Workbook
Name IQ_CH: 110000
Name IQ_CQ: 5000
Name IQ_CY: 10000
Name IQ_DAILY: 500000
Name IQ_FH: 100000
Name IQ_FQ: 500
Name IQ_FY: 1000
Name IQ_LTM: 2000
Name IQ_MONTH: 15000
Name IQ_NTM: 6000
Name IQ_WEEK: 50000
Name IQ_YTD: 3000

Sheet Input Sheet
B3: Please provide the below inputs
B5: Name of the company | C5: Eicher Motors
B7: WACC Inputs
B8: Country | C8: India
B9: Local Currency 10Y Government Bond Yield | C9: 0.0654
B10: =C8&"'s" &" Moodys Sovereign Rating" -> India's Moodys Sovereign Rating | C10: =VLOOKUP(C8,'Damodaran data'!B3:D160,3,FALSE) -> Baa3
B11: Credit default spread as per Dr Damodaran | C11: =VLOOKUP(C8,'Damodaran data'!B3:E160,4,FALSE) -> 0.021609858
B12: Implied US Equity Risk Premium | C12: 0.0373
B13: Asset Beta | C13: 0.72
B14: Asset Beta Variation (+/-) | C14: 0.05
B15: Debt to Equity | C15: ='Assumptions Working'!J816 -> 0.012512391
B16: Debt to Capital (Gearing) | C16: ='Assumptions Working'!J817 -> 0.012357765
B17: Marginal Tax Rate | C17: 0.2512
B18: Company Credit Rating Available? | C18: Yes
B19: Company is Large Firm or Small Firm? | C19: L | F19: L | G19: Yes
B20: Provide Credit Rating | C20: Aaa/AAA | F20: S | G20: No
B21: Interest Coverage Ratio | C21: ='3StatementModel'!H30/'3StatementModel'!H34 -> 73.292234
B22: ICR Based Corporate Default Spread | C22: =IF(C19="L",VLOOKUP(C21,'Damodaran data'!J6:M21,4,TRUE),VLOOKUP('Input Sheet'!C21,'Damodaran data'!P6:S21,4,TRUE)) -> 0.0045
B23: Small Size Premium | C23: 0
B24: Asset Specific Risk Premium | C24: 0

Sheet WACC
B2: ='Input Sheet'!C5 -> Eicher Motors
B3: Weighted Average Cost of Capital
B5: Particulars | D5: Low | E5: Mid | F5: High | H5: Risk Free Rate
B6: Risk Free Rate | D6: ='Input Sheet'!C9-'Input Sheet'!C11 -> 0.043790142 | E6: =D6 -> 0.043790142 | F6: =E6 -> 0.043790142 | H6: ="We have considered "&TEXT(E6,"0.00%")&" as the risk free rate in estimation of cost of equity of "&TEXT(E11,"0.00%")&". The risk free rate of India is calculated by considering local currency 10 years government bond yield adjusted for default spread of India." -> We have considered 4.38% as the risk free rate in estimation of cost of equity of 8.66%. The risk free rate of India is calculated by considering local currency 10 years government bond yield adjusted for default spread of India.
B7: Equity Risk Premium | D7: ='Input Sheet'!C12+'Input Sheet'!C11 -> 0.058909858 | E7: =D7 -> 0.058909858 | F7: =E7 -> 0.058909858
B8: Asset Beta | D8: =E8-'Input Sheet'!C14 -> 0.67 | E8: ='Input Sheet'!C13 -> 0.72 | F8: =E8+'Input Sheet'!C14 -> 0.77
B9: D/E Ratio | D9: ='Input Sheet'!$C$15 -> 0.012512391 | E9: ='Input Sheet'!$C$15 -> 0.012512391 | F9: ='Input Sheet'!$C$15 -> 0.012512391
B10: Equity Beta | D10: =D8*(1+(D9*(1-'Input Sheet'!$C$17))) -> 0.67627742 | E10: =E8*(1+(E9*(1-'Input Sheet'!$C$17))) -> 0.72674588 | F10: =F8*(1+(F9*(1-'Input Sheet'!$C$17))) -> 0.77721434 | H10: Asset Beta
B11: CAPM Cost of Equity | D11: =D6+D7*D10 -> 0.083629548 | E11: =E6+E7*E10 -> 0.086602639 | F11: =F6+F7*F10 -> 0.089575729 | H11: ="We have estimated an asset beta range of "&TEXT(D8,"0.00")&" to "&TEXT(F8,"0.00")& ", with a mid point of "&TEXT(E8,"0.00")& " based on observed median 5 year monthly asset beta of benchmark listed companies adjusted for blume effect." -> We have estimated an asset beta range of 0.67 to 0.77, with a mid point of 0.72 based on observed median 5 year monthly asset beta of benchmark listed companies adjusted for blume effect.
B13: Small Size Premium | D13: 0.025 | E13: =D13 -> 0.025 | F13: =E13 -> 0.025
B14: Asset Specific Premium | D14: ='Input Sheet'!C24 -> 0 | E14: =D14 -> 0 | F14: =E14 -> 0
B15: Modified Cost of Equity | D15: =D11+D13+D14 -> 0.10862955 | E15: =E11+E13+E14 -> 0.11160264 | F15: =F11+F13+F14 -> 0.11457573 | H15: Equity Risk Premium
H16: ="An ERP of "&TEXT(E7,"0.00%")&" has been adopted based on US implied equity risk premium, relative equity volatility of ICE BoFA Public Sector Issues Emerging Markets Index, S&P Emerging BMI Index and country risk premium of India." -> An ERP of 5.89% has been adopted based on US implied equity risk premium, relative equity volatility of ICE BoFA Public Sector Issues Emerging Markets Index, S&P Emerging BMI Index and country risk premium of India.
B17: Pre Tax Cost of Debt | D17: ='Input Sheet'!C9+(IF('Input Sheet'!C18="No",'Input Sheet'!C22,VLOOKUP('Input Sheet'!C20,'Damodaran data'!L7:M21,2,FALSE))) -> 0.0699 | E17: =D17 -> 0.0699 | F17: =E17 -> 0.0699
B18: Marginal Tax Rate | D18: ='Input Sheet'!C17 -> 0.2512 | E18: =D18 -> 0.2512 | F18: =E18 -> 0.2512
B19: Post Tax Cost of Debt | D19: =D17*(1-D18) -> 0.05234112 | E19: =E17*(1-E18) -> 0.05234112 | F19: =F17*(1-F18) -> 0.05234112
H20: Cost of Debt
B21: Capital Gearing (D/D+E) | D21: ='Input Sheet'!C16 -> 0.012357765 | E21: =D21 -> 0.012357765 | F21: =E21 -> 0.012357765 | H21: For the purpose of assessing the cost of debt, we have used country's risk free rate, country's default spread and corporate default spread based on company's debt rating and interest coverage ratio.
B22: Weighted Average Cost of Capital | D22: =(D19*D21)+(D15*(1-D21)) -> 0.10793395 | E22: =(E19*E21)+(E15*(1-E21)) -> 0.1108703 | F22: =(F19*F21)+(F15*(1-F21)) -> 0.11380665
B23: Weighted Average Cost of Capital (Rounded) | D23: =ROUNDUP(D22,2) -> 0.11 | E23: =ROUNDUP(E22,2) -> 0.12 | F23: =ROUNDUP(F22,2) -> 0.12
H25: Small Size Premium
B26: 1. Tax rate considered as Marginal Tax Rate of India. | H26: Emperically small sized assets have exceeded the returns as compared to large sized assets. We have used the study on size premium conducted by Incwert which is based on difference between actual returns and CAPM expected returns arranged in decile basis market capitalization of Indian Companies.
B27: 2. Asset Beta is considered as median of 5 years beta of comps adjusted for blume effect
B28: 3. Equity Beta = Asset Beta * (1+(1-Tax Rate%)*Debt/Equity)
V30: Note | W30: Realisitic Forecasting | Z30: 0.073 | AA30: 25000
H31: Asset Specific Premium | W31: Actual Forecasting | Z31: 0.11 | AA31: 25000
W32: Asset Specific Premium | Z32: =Z31-Z30 -> 0.037
Q39: Source - Incwert Size Premia Study
B50: =B2 -> Eicher Motors | M50: 0.2512
B51: Beta Analysis - 2 Years Weekly
B53: Company Name | D53: Ticker | E53: No. of Weekly Observations | F53: Market Cap (in Crs.) | G53: Asset Beta | H53: 2 years avg D/E | I53: Equity beta | J53: 2 years avg D/D+E | L53: Considered? | M53: Narrow Set
B54: Bajaj Auto | C54: 252955 | D54: NSE: BAJAJ-AUTO | E54: 104 | F54: 251827 | G54: =I54/(1+(H54*(1-$M$50))) -> 0.95424477 | H54: 0.162 | I54: 1.07 | J54: 0.13 | L54: Y | M54: =IF(L54="Y","TRUE","FALSE") -> TRUE
B55: TVS Motors | C55: 167428 | D55: NSE: TVSMOTOR | E55: 104 | F55: 164107 | G55: =I55/(1+(H55*(1-$M$50))) -> 0.24754 | H55: 3.52 | I55: 0.9 | J55: 0.77 | L55: Y | M55: =IF(L55="Y","TRUE","FALSE") -> TRUE
B56: Hero Motorcorp | C56: 108599 | D56: NSE: HEROMOTOCO | E56: 104 | F56: 120299 | G56: =I56/(1+(H56*(1-$M$50))) -> 1.2808185 | H56: 0.02 | I56: 1.3 | J56: 0.02 | L56: Y | M56: =IF(L56="Y","TRUE","FALSE") -> TRUE
B57: Mahindra & Mahindra Ltd | C57: 445718 | D57: NSE: M&M | E57: 104 | F57: 460522 | G57: =I57/(1+(H57*(1-$M$50))) -> 0.54844345 | H57: 1.27 | I57: 1.07 | J57: 0.55 | L57: Y | M57: =IF(L57="Y","TRUE","FALSE") -> TRUE
B58: Ashok Leyland Ltd | C58: 81882 | D58: NSE: ASHOKLEY | E58: 104 | F58: 85048 | G58: =I58/(1+(H58*(1-$M$50))) -> 0.14929476 | H58: 4.3 | I58: 0.63 | J58: 0.8 | L58: N | M58: =IF(L58="Y","TRUE","FALSE") -> FALSE
B60: Median - Broad Set | G60: =MEDIAN(G54:G58) -> 0.54844345 | H60: =MEDIAN(H54:H58) -> 1.27 | I60: =MEDIAN(I54:I58) -> 1.07 | J60: =MEDIAN(J54:J58) -> 0.55
B61: Average - Broad Set | G61: =AVERAGE(G54:G58) -> 0.63606829 | H61: =AVERAGE(H54:H58) -> 1.8544 | I61: =AVERAGE(I54:I58) -> 0.994 | J61: =AVERAGE(J54:J58) -> 0.454
B63: Median - Considered Set | G63: {=MEDIAN(IF($M$54:$M$58,G54:G58))} -> 0.75134411 | H63: {=MEDIAN(IF($M$54:$M$58,H54:H58))} -> 0.716 | I63: {=MEDIAN(IF($M$54:$M$58,I54:I58))} -> 1.07 | J63: {=MEDIAN(IF($M$54:$M$58,J54:J58))} -> 0.34
B64: Average - Considered Set | G64: {=AVERAGE(IF($M$54:$M$58,G54:G58))} -> 0.75776167 | H64: {=AVERAGE(IF($M$54:$M$58,H54:H58))} -> 1.243 | I64: {=AVERAGE(IF($M$54:$M$58,I54:I58))} -> 1.085 | J64: {=AVERAGE(IF($M$54:$M$58,J54:J58))} -> 0.3675
...

Sheet Damodaran data
B2: Country Data | J2: Company Data
B3: Country | C3: Africa | D3: Moody's rating | E3: Rating-based Default Spread
B4: India | C4: Asia | D4: Baa3 | E4: 0.021609858 | J4: For large non-financial service firms | P4: For smaller and riskier firms
B5: United Kingdom | C5: Western Europe | D5: Aa3 | E5: 0.0058935977 | J5: If interest coverage ratio is | P5: If interest coverage ratio is
B6: United States | C6: North America | D6: Aa1 | E6: 0.0027 | J6: > | K6: ≤ to | L6: Rating is | M6: Spread is | P6: greater than | Q6: ≤ to | R6: Rating is | S6: Spread is
B7: Abu Dhabi | C7: Middle East | D7: Aa2 | E7: 0.004853551 | J7: -100000 | K7: 0.199999 | L7: D2/D | M7: 0.19 | P7: -100000 | Q7: 0.499999 | R7: D2/D | S7: 0.19
B8: Albania | C8: Eastern Europe & Russia | D8: Ba3 | E8: 0.035361586 | J8: 0.2 | K8: 0.649999 | L8: C2/C | M8: 0.155 | P8: 0.5 | Q8: 0.799999 | R8: C2/C | S8: 0.155
B9: Andorra (Principality of) | C9: Western Europe | D9: Baa1 | E9: 0.015716261 | J9: 0.65 | K9: 0.799999 | L9: Ca2/CC | M9: 0.101 | P9: 0.8 | Q9: 1.249999 | R9: Ca2/CC | S9: 0.101
B10: Angola | C10: Africa | D10: B3 | E10: 0.063905089 | J10: 0.8 | K10: 1.249999 | L10: Caa/CCC | M10: 0.0728 | P10: 1.25 | Q10: 1.499999 | R10: Caa/CCC | S10: 0.0728
B11: Argentina | C11: Central and South America | D11: Caa3 | E11: 0.098342189 | J11: 1.25 | K11: 1.499999 | L11: B3/B- | M11: 0.0442 | P11: 1.5 | Q11: 1.999999 | R11: B3/B- | S11: 0.0442
B12: Armenia | C12: Eastern Europe & Russia | D12: Ba3 | E12: 0.035361586 | J12: 1.5 | K12: 1.749999 | L12: B2/B | M12: 0.03 | P12: 2 | Q12: 2.499999 | R12: B2/B | S12: 0.03
B13: Aruba | C13: Caribbean | D13: Baa3 | E13: 0.021609858 | J13: 1.75 | K13: 1.999999 | L13: B1/B+ | M13: 0.0261 | P13: 2.5 | Q13: 2.999999 | R13: B1/B+ | S13: 0.0261
B14: Australia | C14: Australia & New Zealand | D14: Aaa | E14: 0 | J14: 2 | K14: 2.2499999 | L14: Ba2/BB | M14: 0.0183 | P14: 3 | Q14: 3.499999 | R14: Ba2/BB | S14: 0.0183
B15: Austria | C15: Western Europe | D15: Aa1 | E15: 0.0027 | J15: 2.25 | K15: 2.49999 | L15: Ba1/BB+ | M15: 0.0155 | P15: 3.5 | Q15: 3.9999999 | R15: Ba1/BB+ | S15: 0.0155
B16: Azerbaijan | C16: Eastern Europe & Russia | D16: Baa3 | E16: 0.021609858 | J16: 2.5 | K16: 2.999999 | L16: Baa2/BBB | M16: 0.012 | P16: 4 | Q16: 4.499999 | R16: Baa2/BBB | S16: 0.012
B17: Bahamas | C17: Caribbean | D17: B1 | E17: 0.044259763 | J17: 3 | K17: 4.249999 | L17: A3/A- | M17: 0.0095 | P17: 4.5 | Q17: 5.999999 | R17: A3/A- | S17: 0.0095
B18: Bahrain | C18: Middle East | D18: B2 | E18: 0.054082426 | J18: 4.25 | K18: 5.499999 | L18: A2/A | M18: 0.0085 | P18: 6 | Q18: 7.499999 | R18: A2/A | S18: 0.0085
... B21: Belarus | C21: Eastern Europe & Russia | D21: C | E21: 0.175 | J21: 8.5 | K21: 100000 | L21: Aaa/AAA | M21: 0.0045 | P21: 12.5 | Q21: 100000 | R21: Aaa/AAA | S21: 0.0045
B22: Belgium | C22: Western Europe | D22: Aa3 | E22: 0.0058935977
B23: Belize | C23: Central and South America | D23: Caa1 | E23: 0.073727752
B24: Benin | C24: Africa | D24: B1 | E24: 0.044259763
B25: Bermuda | C25: Caribbean | D25: A2 | E25: 0.0083203732
B26: Bolivia | C26: Central and South America | D26: Ca | E26: 0.11798751
B27: Bosnia and Herzegovina | C27: Eastern Europe & Russia | D27: B3 | E27: 0.063905089
B28: Botswana | C28: Africa | D28: A3 | E28: 0.011787195
B29: Brazil | C29: Central and South America | D29: Ba1 | E29: 0.024614437
B30: Bulgaria | C30: Eastern Europe & Russia | D30: Baa1 | E30: 0.015716261
B31: Burkina Faso | C31: Africa | D31: Caa1 | E31: 0.073727752
B32: Cambodia | C32: Asia | D32: B2 | E32: 0.054082426
B33: Cameroon | C33: Africa | D33: Caa1 | E33: 0.073727752
... B160: Zambia | C160: Africa | D160: Caa2 | E160: 0.088519526

Sheet Controlsheet
B2: ='Input Sheet'!C5 -> Eicher Motors
B3: Control Sheet | Q3: Mangement Case
F4: Current Case: | G4: 2 | Q4: Base Case
Q5: Down Case
H8: Actual | I8: Explicit Forecast Period | N8: Maturity Period
B9: In INR Crores unless stated otherwise | D9: 2021 | E9: =D9+1 -> 2022 | F9: =E9+1 -> 2023 | G9: =F9+1 -> 2024 | H9: =G9+1 -> 2025 | I9: =H9+1 -> 2026 | J9: =I9+1 -> 2027 | K9: =J9+1 -> 2028 | L9: =K9+1 -> 2029 | ... R9: =Q9+1 -> 2035
B11: Assumptions
A13: # | B13: Revenue
B15: Revenue - yoy% growth
B16: Mangement Case | D16: ='ConsolidatedP&L'!E8 -> -0.047329023 | E16: ='ConsolidatedP&L'!F8 -> 0.18089641 | F16: ='ConsolidatedP&L'!G8 -> 0.40244887 | G16: ='ConsolidatedP&L'!H8 -> 0.14496426 | H16: ='ConsolidatedP&L'!I8 -> 0.14118294 | I16: 0.15 | J16: =I16-(($I$16-$M$16)/($M$9-$I$9)) -> 0.1425 | K16: =J16-(($I$16-$M$16)/($M$9-$I$9)) -> 0.135 | L16: =K16-(($I$16-$M$16)/($M$9-$I$9)) -> 0.1275 | M16: 0.12 | N16: 0.12 | O16: 0.12 | P16: 0.12 | Q16: 0.12 | R16: 0.12
B17: Base Case | D17: =D16 -> -0.047329023 | E17: =E16 -> 0.18089641 | F17: =F16 -> 0.40244887 | G17: =G16 -> 0.14496426 | H17: =H16 -> 0.14118294 | I17: 0.15 | J17: =I17-(($I$17-$M$17)/($M$9-$I$9)) -> 0.1425 | K17: =J17-(($I$17-$M$17)/($M$9-$I$9)) -> 0.135 | L17: =K17-(($I$17-$M$17)/($M$9-$I$9)) -> 0.1275 | M17: 0.12 | N17: 0.12 | O17: 0.12 | P17: 0.12 | Q17: 0.12 | R17: 0.12
B18: Down Case | D18: =D17 -> -0.047329023 | E18: =E17 -> 0.18089641 | F18: =F17 -> 0.40244887 | G18: =G17 -> 0.14496426 | H18: =H17 -> 0.14118294 | I18: 0.07 | J18: =I18-(($I$18-$M$18)/($M$9-$I$9)) -> 0.0725 | K18: =J18-(($I$17-$M$17)/($M$9-$I$9)) -> 0.065 | L18: =K18-(($I$17-$M$17)/($M$9-$I$9)) -> 0.0575 | M18: 0.08 | N18: 0.08 | O18: 0.08 | P18: 0.08 | Q18: 0.08 | R18: 0.08
B19: ="Current Case - "&CHOOSE($G$4,B16,B17,B18) -> Current Case - Base Case | I19: =CHOOSE($G$4,I16,I17,I18) -> 0.15 | J19: =CHOOSE($G$4,J16,J17,J18) -> 0.1425 | K19: =CHOOSE($G$4,K16,K17,K18) -> 0.135 | L19: =CHOOSE($G$4,L16,L17,L18) -> 0.1275 | M19: =CHOOSE($G$4,M16,M17,M18) -> 0.12 | N19: =CHOOSE($G$4,N16,N17,N18) -> 0.12 | O19: =CHOOSE($G$4,O16,O17,O18) -> 0.12 | P19: =CHOOSE($G$4,P16,P17,P18) -> 0.12 | ... R19: =CHOOSE($G$4,R16,R17,R18) -> 0.12
A22: # | B22: COGS
B24: Gross Margin%
B25: Mangement Case | D25: ='ConsolidatedP&L'!C19 -> 0.48378595 | E25: ='ConsolidatedP&L'!D19 -> 0.45420917 | F25: ='ConsolidatedP&L'!E19 -> 0.41375404 | G25: ='ConsolidatedP&L'!F19 -> 0.4216568 | H25: ='ConsolidatedP&L'!G19 -> 0.43139471 | I25: 0.45 | J25: 0.45 | K25: 0.45 | L25: 0.45 | M25: 0.454 | N25: 0.454 | O25: 0.454 | P25: 0.454 | Q25: 0.454 | R25: 0.454
B26: Base Case | D26: =D25 -> 0.48378595 | E26: =E25 -> 0.45420917 | F26: =F25 -> 0.41375404 | G26: =G25 -> 0.4216568 | H26: =H25 -> 0.43139471 | I26: 0.45 | J26: =I26-(($I$26-$M$26)/($M$9-$I$9)) -> 0.444 | K26: =J26-(($I$26-$M$26)/($M$9-$I$9)) -> 0.438 | L26: =K26-(($I$26-$M$26)/($M$9-$I$9)) -> 0.432 | M26: 0.426 | N26: 0.426 | O26: 0.426 | P26: 0.426 | Q26: 0.426 | R26: 0.426
B27: Down Case | D27: =D26 -> 0.48378595 | E27: =E26 -> 0.45420917 | F27: =F26 -> 0.41375404 | G27: =G26 -> 0.4216568 | H27: =H26 -> 0.43139471 | I27: 0.42 | J27: =I27-(($I$27-$M$27)/($M$9-$I$9)) -> 0.41275 | K27: =J27-(($I$27-$M$27)/($M$9-$I$9)) -> 0.4055 | L27: =K27-(($I$27-$M$27)/($M$9-$I$9)) -> 0.39825 | M27: 0.391 | N27: 0.391 | O27: 0.391 | P27: 0.391 | Q27: 0.391 | R27: 0.391
B28: ="Current Case - "&CHOOSE($G$4,B25,B26,B27) -> Current Case - Base Case | I28: =CHOOSE($G$4,I25,I26,I27) -> 0.45 | J28: =CHOOSE($G$4,J25,J26,J27) -> 0.444 | K28: =CHOOSE($G$4,K25,K26,K27) -> 0.438 | L28: =CHOOSE($G$4,L25,L26,L27) -> 0.432 | M28: =CHOOSE($G$4,M25,M26,M27) -> 0.426 | N28: =CHOOSE($G$4,N25,N26,N27) -> 0.426 | O28: =CHOOSE($G$4,O25,O26,O27) -> 0.426 | P28: =CHOOSE($G$4,P25,P26,P27) -> 0.426 | ... R28: =CHOOSE($G$4,R25,R26,R27) -> 0.426
B30: Current Case - COGS % Sales | I30: =1-I28 -> 0.55 | J30: =1-J28 -> 0.556 | K30: =1-K28 -> 0.562 | L30: =1-L28 -> 0.568 | M30: =1-M28 -> 0.574 | N30: =1-N28 -> 0.574 | O30: =1-O28 -> 0.574 | P30: =1-P28 -> 0.574 | ... R30: =1-R28 -> 0.574
A33: # | B33: Selling, General and Administration (SG&A)
B35: Selling, General and Administration (SG&A)
B36: Mangement Case | D36: 0.096696807 | E36: 0.096696807 | F36: 0.096696807 | G36: 0.096696807 | H36: 0.096696807 | I36: 0.075 | J36: 0.075 | K36: 0.075 | L36: 0.075 | M36: 0.075 | N36: 0.075 | O36: 0.075 | P36: 0.075 | Q36: 0.075 | R36: 0.075
B37: Base Case | D37: =D36 -> 0.096696807 | E37: =E36 -> 0.096696807 | F37: =F36 -> 0.096696807 | G37: =G36 -> 0.096696807 | H37: =H36 -> 0.096696807 | I37: 0.075 | J37: 0.075 | K37: 0.075 | L37: 0.075 | M37: 0.075 | N37: 0.075 | O37: 0.075 | P37: 0.075 | Q37: 0.075 | R37: 0.075
B38: Down Case | D38: =D37 -> 0.096696807 | E38: =E37 -> 0.096696807 | F38: =F37 -> 0.096696807 | G38: =G37 -> 0.096696807 | H38: =H37 -> 0.096696807 | I38: 0.075 | J38: 0.075 | K38: 0.075 | L38: 0.075 | M38: 0.075 | N38: 0.075 | O38: 0.075 | P38: 0.075 | Q38: 0.075 | R38: 0.075
B39: ="Current Case - "&CHOOSE($G$4,B36,B37,B38) -> Current Case - Base Case | I39: =CHOOSE($G$4,I36,I37,I38) -> 0.075 | J39: =CHOOSE($G$4,J36,J37,J38) -> 0.075 | K39: =CHOOSE($G$4,K36,K37,K38) -> 0.075 | L39: =CHOOSE($G$4,L36,L37,L38) -> 0.075 | M39: =CHOOSE($G$4,M36,M37,M38) -> 0.075 | N39: =CHOOSE($G$4,N36,N37,N38) -> 0.075 | O39: =CHOOSE($G$4,O36,O37,O38) -> 0.075 | P39: =CHOOSE($G$4,P36,P37,P38) -> 0.075 | ... R39: =CHOOSE($G$4,R36,R37,R38) -> 0.075
B41: ='Assumptions Working'!B251 -> Consumption of Stores and machinery spares % Revenue
B42: Mangement Case | D42: 0.015998211 | E42: 0.019281732 | F42: 0.018158616 | G42: 0.014461973 | H42: 0.015185728 | I42: 0.017 | J42: 0.017 | K42: 0.017 | L42: 0.017 | M42: 0.017 | N42: 0.017 | O42: 0.017 | P42: 0.017 | Q42: 0.017 | R42: 0.017
B43: Base Case | D43: =D42 -> 0.015998211 | E43: =E42 -> 0.019281732 | F43: =F42 -> 0.018158616 | G43: =G42 -> 0.014461973 | H43: =H42 -> 0.015185728 | I43: 0.017 | J43: 0.017 | K43: 0.017 | L43: 0.017 | M43: 0.017 | N43: 0.017 | O43: 0.017 | P43: 0.017 | Q43: 0.017 | R43: 0.017
B44: Down Case | D44: =D43 -> 0.015998211 | E44: =E43 -> 0.019281732 | F44: =F43 -> 0.018158616 | G44: =G43 -> 0.014461973 | H44: =H43 -> 0.015185728 | I44: 0.017 | J44: 0.017 | K44: 0.017 | L44: 0.017 | M44: 0.017 | N44: 0.017 | O44: 0.017 | P44: 0.017 | Q44: 0.017 | R44: 0.017
B45: ="Current Case - "&CHOOSE($G$4,B42,B43,B44) -> Current Case - Base Case | I45: =CHOOSE($G$4,I42,I43,I44) -> 0.017 | J45: =CHOOSE($G$4,J42,J43,J44) -> 0.017 | K45: =CHOOSE($G$4,K42,K43,K44) -> 0.017 | L45: =CHOOSE($G$4,L42,L43,L44) -> 0.017 | M45: =CHOOSE($G$4,M42,M43,M44) -> 0.017 | N45: =CHOOSE($G$4,N42,N43,N44) -> 0.017 | O45: =CHOOSE($G$4,O42,O43,O44) -> 0.017 | P45: =CHOOSE($G$4,P42,P43,P44) -> 0.017 | ... R45: =CHOOSE($G$4,R42,R43,R44) -> 0.017
B47: ='Assumptions Working'!B254 -> Freight and handling charges % Revenue
B48: Mangement Case | D48: 0.013887057 | E48: 0.017573605 | F48: 0.018891192 | G48: 0.016060325 | H48: 0.017521668 | I48: 0.016 | J48: 0.016 | K48: 0.016 | L48: 0.016 | M48: 0.016 | N48: 0.016 | O48: 0.016 | P48: 0.016 | Q48: 0.016 | R48: 0.016
B49: Base Case | D49: =D48 -> 0.013887057 | E49: =E48 -> 0.017573605 | F49: =F48 -> 0.018891192 | G49: =G48 -> 0.016060325 | H49: =H48 -> 0.017521668 | I49: 0.016 | J49: 0.016 | K49: 0.016 | L49: 0.016 | M49: 0.016 | N49: 0.016 | O49: 0.016 | P49: 0.016 | Q49: 0.016 | R49: 0.016
B50: Down Case | D50: =D49 -> 0.013887057 | E50: =E49 -> 0.017573605 | F50: =F49 -> 0.018891192 | G50: =G49 -> 0.016060325 | H50: =H49 -> 0.017521668 | I50: 0.016 | J50: 0.016 | K50: 0.016 | L50: 0.016 | M50: 0.016 | N50: 0.016 | O50: 0.016 | P50: 0.016 | Q50: 0.016 | R50: 0.016
B51: ="Current Case - "&CHOOSE($G$4,B48,B49,B50) -> Current Case - Base Case | I51: =CHOOSE($G$4,I48,I49,I50) -> 0.016 | J51: =CHOOSE($G$4,J48,J49,J50) -> 0.016 | K51: =CHOOSE($G$4,K48,K49,K50) -> 0.016 | L51: =CHOOSE($G$4,L48,L49,L50) -> 0.016 | M51: =CHOOSE($G$4,M48,M49,M50) -> 0.016 | N51: =CHOOSE($G$4,N48,N49,N50) -> 0.016 | O51: =CHOOSE($G$4,O48,O49,O50) -> 0.016 | P51: =CHOOSE($G$4,P48,P49,P50) -> 0.016 | ... R51: =CHOOSE($G$4,R48,R49,R50) -> 0.016
B53: ='Assumptions Working'!B257 -> Selling and distribution expenses % Revenue
B54: Mangement Case | D54: 0.02074802 | E54: 0.02764563 | F54: 0.029523936 | G54: 0.033031402 | H54: 0.040321457 | I54: 0.028 | J54: 0.028 | K54: 0.028 | L54: 0.028 | M54: 0.028 | N54: 0.028 | O54: 0.028 | P54: 0.028 | Q54: 0.028 | R54: 0.028
B55: Base Case | D55: =D54 -> 0.02074802 | E55: =E54 -> 0.02764563 | F55: =F54 -> 0.029523936 | G55: =G54 -> 0.033031402 | H55: =H54 -> 0.040321457 | I55: 0.028 | J55: 0.028 | K55: 0.028 | L55: 0.028 | M55: 0.028 | N55: 0.028 | O55: 0.028 | P55: 0.028 | Q55: 0.028 | R55: 0.028
B56: Down Case | D56: =D55 -> 0.02074802 | E56: =E55 -> 0.02764563 | F56: =F55 -> 0.029523936 | G56: =G55 -> 0.033031402 | H56: =H55 -> 0.040321457 | I56: 0.028 | J56: 0.028 | K56: 0.028 | L56: 0.028 | M56: 0.028 | N56: 0.028 | O56: 0.028 | P56: 0.028 | Q56: 0.028 | R56: 0.028
...

Sheet Schedules
B2: ='Input Sheet'!C5 -> Eicher Motors
B3: Schedule Sheet
H4: Current Case: | I4: 0
H8: Actual | I8: Explicit Forecast Period | N8: Maturity Period
B9: In INR Crores unless stated otherwise | D9: =Controlsheet!D9 -> 2021 | E9: =Controlsheet!E9 -> 2022 | F9: =Controlsheet!F9 -> 2023 | G9: =Controlsheet!G9 -> 2024 | H9: =Controlsheet!H9 -> 2025 | I9: =H9+1 -> 2026 | J9: =I9+1 -> 2027 | K9: =J9+1 -> 2028 | L9: =K9+1 -> 2029 | M9: =L9+1 -> 2030 | N9: =M9+1 -> 2031 | O9: =N9+1 -> 2032 | P9: =O9+1 -> 2033 | ... R9: =Q9+1 -> 2035
A11: # | B11: Revenue Schedule
B13: Revenue | D13: ='ConsolidatedP&L'!E6 -> 8720.35 | E13: ='ConsolidatedP&L'!F6 -> 10297.83 | F13: ='ConsolidatedP&L'!G6 -> 14442.18 | G13: ='ConsolidatedP&L'!H6 -> 16535.78 | H13: ='ConsolidatedP&L'!I6 -> 18870.35 | I13: =H13*(1+I15) -> 21700.902 | J13: =I13*(1+J15) -> 24793.281 | K13: =J13*(1+K15) -> 28140.374 | L13: =K13*(1+L15) -> 31728.272 | M13: =L13*(1+M15) -> 35535.664 | N13: =M13*(1+N15) -> 39799.944 | O13: =N13*(1+O15) -> 44575.937 | P13: =O13*(1+P15) -> 49925.05 | ... R13: =Q13*(1+R15) -> 62625.983
B15: Growth YoY% | E15: =E13/D13-1 -> 0.18089641 | F15: =F13/E13-1 -> 0.40244887 | G15: =G13/F13-1 -> 0.14496426 | H15: =H13/G13-1 -> 0.14118294 | I15: =Controlsheet!I19 -> 0.15 | J15: =Controlsheet!J19 -> 0.1425 | K15: =Controlsheet!K19 -> 0.135 | L15: =Controlsheet!L19 -> 0.1275 | M15: =Controlsheet!M19 -> 0.12 | N15: =Controlsheet!N19 -> 0.12 | O15: =Controlsheet!O19 -> 0.12 | P15: =Controlsheet!P19 -> 0.12 | ... R15: =Controlsheet!R19 -> 0.12
A17: # | B17: COGS Schedule
B20: COGS | D20: ='ConsolidatedP&L'!E16*-1 -> 5112.27 | E20: ='ConsolidatedP&L'!F16*-1 -> 5955.68 | F20: ='ConsolidatedP&L'!G16*-1 -> 8211.9 | G20: ='ConsolidatedP&L'!H16*-1 -> 8980.65 | H20: ='ConsolidatedP&L'!I16*-1 -> 10297.08 | I20: =I13*I22 -> 11935.496 | J20: =J13*J22 -> 13785.064 | K20: =K13*K22 -> 15814.89 | L20: =L13*L22 -> 18021.658 | M20: =M13*M22 -> 20397.471 | N20: =N13*N22 -> 22845.168 | O20: =O13*O22 -> 25586.588 | P20: =P13*P22 -> 28656.979 | ... R20: =R13*R22 -> 35947.314
B22: COGS % Sales | D22: =D20/D13 -> 0.58624596 | E22: =E20/E13 -> 0.5783432 | F22: =F20/F13 -> 0.56860529 | G22: =G20/G13 -> 0.54310411 | H22: =H20/H13 -> 0.54567509 | I22: =Controlsheet!I30 -> 0.55 | J22: =Controlsheet!J30 -> 0.556 | K22: =Controlsheet!K30 -> 0.562 | L22: =Controlsheet!L30 -> 0.568 | M22: =Controlsheet!M30 -> 0.574 | N22: =Controlsheet!N30 -> 0.574 | O22: =Controlsheet!O30 -> 0.574 | P22: =Controlsheet!P30 -> 0.574 | ... R22: =Controlsheet!R30 -> 0.574
A24: # | B24: SG&A (Excluding Depreciation & Interest Expenses) Schedule
B26: Employee Benefit Expense
B28: Employee Benefit Expense | D28: ='Assumptions Working'!F247 -> 843.23 | E28: ='Assumptions Working'!G247 -> 821.02 | F28: ='Assumptions Working'!H247 -> 1001.93 | G28: ='Assumptions Working'!I247 -> 1235.69 | H28: ='Assumptions Working'!J247 -> 1391.23 | I28: =I$13*I29 -> 1627.5677 | J28: =J$13*J29 -> 1859.4961 | K28: =K$13*K29 -> 2110.5281 | L28: =L$13*L29 -> 2379.6204 | M28: =M$13*M29 -> 2665.1748 | N28: =N$13*N29 -> 2984.9958 | O28: =O$13*O29 -> 3343.1953 | P28: =P$13*P29 -> 3744.3787 | ... R28: =R$13*R29 -> 4696.9487
B29: Employee Benefit Expense % Revenue | D29: ='Assumptions Working'!F248 -> 0.096696807 | E29: ='Assumptions Working'!G248 -> 0.079727477 | F29: ='Assumptions Working'!H248 -> 0.069375261 | G29: ='Assumptions Working'!I248 -> 0.074728256 | H29: ='Assumptions Working'!J248 -> 0.073725713 | I29: =Controlsheet!I39 -> 0.075 | J29: =Controlsheet!J39 -> 0.075 | K29: =Controlsheet!K39 -> 0.075 | L29: =Controlsheet!L39 -> 0.075 | M29: =Controlsheet!M39 -> 0.075 | N29: =Controlsheet!N39 -> 0.075 | O29: =Controlsheet!O39 -> 0.075 | P29: =Controlsheet!P39 -> 0.075 | ... R29: =Controlsheet!R39 -> 0.075
B31: Consumption of Stores and machinery spares
B33: Consumption of Stores and machinery spares | D33: ='Assumptions Working'!F250 -> 139.51 | E33: ='Assumptions Working'!G250 -> 198.56 | F33: ='Assumptions Working'!H250 -> 262.25 | G33: ='Assumptions Working'!I250 -> 239.14 | H33: ='Assumptions Working'!J250 -> 286.56 | I33: =I$13*I34 -> 368.91534 | J33: =J$13*J34 -> 421.48578 | K33: =K$13*K34 -> 478.38636 | L33: =L$13*L34 -> 539.38062 | M33: =M$13*M34 -> 604.10629 | N33: =N$13*N34 -> 676.59905 | O33: =O$13*O34 -> 757.79094 | P33: =P$13*P34 -> 848.72585 | ... R33: =R$13*R34 -> 1064.6417
B34: Consumption of Stores and machinery spares % Revenue | D34: ='Assumptions Working'!F251 -> 0.015998211 | E34: ='Assumptions Working'!G251 -> 0.019281732 | F34: ='Assumptions Working'!H251 -> 0.018158616 | G34: ='Assumptions Working'!I251 -> 0.014461973 | H34: ='Assumptions Working'!J251 -> 0.015185728 | I34: =Controlsheet!I45 -> 0.017 | J34: =Controlsheet!J45 -> 0.017 | K34: =Controlsheet!K45 -> 0.017 | L34: =Controlsheet!L45 -> 0.017 | M34: =Controlsheet!M45 -> 0.017 | N34: =Controlsheet!N45 -> 0.017 | O34: =Controlsheet!O45 -> 0.017 | P34: =Controlsheet!P45 -> 0.017 | ... R34: =Controlsheet!R45 -> 0.017
B36: Freight and handling charges
B38: Freight and handling charges | D38: ='Assumptions Working'!F253 -> 121.1 | E38: ='Assumptions Working'!G253 -> 180.97 | F38: ='Assumptions Working'!H253 -> 272.83 | G38: ='Assumptions Working'!I253 -> 265.57 | H38: ='Assumptions Working'!J253 -> 330.64 | I38: =I$13*I39 -> 347.21444 | J38: =J$13*J39 -> 396.6925 | K38: =K$13*K39 -> 450.24598 | L38: =L$13*L39 -> 507.65235 | M38: =M$13*M39 -> 568.57063 | N38: =N$13*N39 -> 636.79911 | O38: =O$13*O39 -> 713.215 | P38: =P$13*P39 -> 798.8008 | ... R38: =R$13*R39 -> 1002.0157
B39: Freight and handling charges % Revenue | D39: ='Assumptions Working'!F254 -> 0.013887057 | E39: ='Assumptions Working'!G254 -> 0.017573605 | F39: ='Assumptions Working'!H254 -> 0.018891192 | G39: ='Assumptions Working'!I254 -> 0.016060325 | H39: ='Assumptions Working'!J254 -> 0.017521668 | I39: =Controlsheet!I51 -> 0.016 | J39: =Controlsheet!J51 -> 0.016 | K39: =Controlsheet!K51 -> 0.016 | L39: =Controlsheet!L51 -> 0.016 | M39: =Controlsheet!M51 -> 0.016 | N39: =Controlsheet!N51 -> 0.016 | O39: =Controlsheet!O51 -> 0.016 | P39: =Controlsheet!P51 -> 0.016 | ... R39: =Controlsheet!R51 -> 0.016
B41: Selling and distribution expenses
B43: Selling and distribution expenses | D43: ='Assumptions Working'!F256 -> 180.93 | E43: ='Assumptions Working'!G256 -> 284.69 | F43: ='Assumptions Working'!H256 -> 426.39 | G43: ='Assumptions Working'!I256 -> 546.2 | H43: ='Assumptions Working'!J256 -> 760.88 | I43: =I$13*I44 -> 607.62527 | J43: =J$13*J44 -> 694.21187 | K43: =K$13*K44 -> 787.93047 | L43: =L$13*L44 -> 888.39161 | M43: =M$13*M44 -> 994.9986 | N43: =N$13*N44 -> 1114.3984 | O43: =O$13*O44 -> 1248.1262 | P43: =P$13*P44 -> 1397.9014 | ... R43: =R$13*R44 -> 1753.5275
B44: Selling and distribution expenses % Revenue | D44: ='Assumptions Working'!F257 -> 0.02074802 | E44: ='Assumptions Working'!G257 -> 0.02764563 | F44: ='Assumptions Working'!H257 -> 0.029523936 | G44: ='Assumptions Working'!I257 -> 0.033031402 | H44: ='Assumptions Working'!J257 -> 0.040321457 | I44: =Controlsheet!I57 -> 0.028 | J44: =Controlsheet!J57 -> 0.028 | K44: =Controlsheet!K57 -> 0.028 | L44: =Controlsheet!L57 -> 0.028 | M44: =Controlsheet!M57 -> 0.028 | N44: =Controlsheet!N57 -> 0.028 | O44: =Controlsheet!O57 -> 0.028 | P44: =Controlsheet!P57 -> 0.028 | ... R44: =Controlsheet!R57 -> 0.028
B46: Other SG&A Expenses
B48: Other SG&A Expenses | D48: ='Assumptions Working'!F259 -> 541.98 | E48: ='Assumptions Working'!G259 -> 684.66 | F48: ='Assumptions Working'!H259 -> 823.3 | G48: ='Assumptions Working'!I259 -> 941.62 | H48: ='Assumptions Working'!J259 -> 1091.93 | I48: =I$13*I49 -> 1323.7551 | J48: =J$13*J49 -> 1512.3901 | K48: =K$13*K49 -> 1716.5628 | L48: =L$13*L49 -> 1935.4246 | M48: =M$13*M49 -> 2167.6755 | N48: =N$13*N49 -> 2427.7966 | O48: =O$13*O49 -> 2719.1322 | P48: =P$13*P49 -> 3045.428 | ... R48: =R$13*R49 -> 3820.1849
B49: Other SG&A Expenses % Revenue | D49: ='Assumptions Working'!F260 -> 0.062151175 | E49: ='Assumptions Working'!G260 -> 0.066485852 | F49: ='Assumptions Working'!H260 -> 0.057006629 | G49: ='Assumptions Working'!I260 -> 0.056944396 | H49: ='Assumptions Working'!J260 -> 0.057864851 | I49: =Controlsheet!I63 -> 0.061 | J49: =Controlsheet!J63 -> 0.061 | K49: =Controlsheet!K63 -> 0.061 | L49: =Controlsheet!L63 -> 0.061 | M49: =Controlsheet!M63 -> 0.061 | N49: =Controlsheet!N63 -> 0.061 | O49: =Controlsheet!O63 -> 0.061 | P49: =Controlsheet!P63 -> 0.061 | ... R49: =Controlsheet!R63 -> 0.061
B51: Total SG&A (Excluding Depreciation & Interest Expenses) | D51: =SUM(D28,D33,D38,D43,D48) -> 1826.75 | E51: =SUM(E28,E33,E38,E43,E48) -> 2169.9 | F51: =SUM(F28,F33,F38,F43,F48) -> 2786.7 | G51: =SUM(G28,G33,G38,G43,G48) -> 3228.22 | H51: =SUM(H28,H33,H38,H43,H48) -> 3861.24 | I51: =SUM(I28,I33,I38,I43,I48) -> 4275.0778 | J51: =SUM(J28,J33,J38,J43,J48) -> 4884.2764 | K51: =SUM(K28,K33,K38,K43,K48) -> 5543.6537 | ... R51: =SUM(R28,R33,R38,R43,R48) -> 12337.319
B52: Total SG&A % Sales | D52: =D51/D13 -> 0.20948127 | E52: =E51/E13 -> 0.2107143 | F52: =F51/F13 -> 0.19295563 | G52: =G51/G13 -> 0.19522635 | H52: =H51/H13 -> 0.20461942 | I52: =I51/I13 -> 0.197 | J52: =J51/J13 -> 0.197 | K52: =K51/K13 -> 0.197 | ... R52: =R51/R13 -> 0.197
A54: # | B54: Non Current Asset Schedule
B56: Property Plant & Equipment
B58: Opening PP&E | I58: =ConsolidatedBS!I6 -> 2268.7 | J58: =I61 -> 2919.4431 | K58: =J61 -> 3450.1861 | L58: =K61 -> 3860.9292 | M58: =L61 -> 4151.6722 | N58: =M61 -> 4322.4153 | O58: =N61 -> 4373.1584 | P58: =O61 -> 4303.9014 | Q58: =P61 -> 4114.6445 | R58: =Q61 -> 3805.3875
B59: Add : Capex during the year | I59: 1200 | J59: 1200 | K59: 1200 | L59: 1200 | M59: 1200 | N59: 1200 | O59: 1200 | P59: 1200 | Q59: 1200 | R59: 1200
B60: Less : Depreciation | H60: =('ConsolidatedP&L'!I35*-1)/(SUM(ConsolidatedBS!I6,ConsolidatedBS!I10,ConsolidatedBS!I9,ConsolidatedBS!I11))*ConsolidatedBS!I6 -> 429.25694 | I60: =H60+I59/$C$114 -> 549.25694 | J60: =I60+J59/$C$114 -> 669.25694 | K60: =J60+K59/$C$114 -> 789.25694 | L60: =K60+L59/$C$114 -> 909.25694 | M60: =L60+M59/$C$114 -> 1029.2569 | N60: =M60+N59/$C$114 -> 1149.2569 | O60: =N60+O59/$C$114 -> 1269.2569 | P60: =O60+P59/$C$114 -> 1389.2569 | ... R60: =Q60+R59/$C$114 -> 1629.2569
B61: Closing PP&E | I61: =I58+I59-I60 -> 2919.4431 | J61: =J58+J59-J60 -> 3450.1861 | K61: =K58+K59-K60 -> 3860.9292 | L61: =L58+L59-L60 -> 4151.6722 | M61: =M58+M59-M60 -> 4322.4153 | N61: =N58+N59-N60 -> 4373.1584 | O61: =O58+O59-O60 -> 4303.9014 | P61: =P58+P59-P60 -> 4114.6445 | ... R61: =R58+R59-R60 -> 3376.1306
B62: YoY Growth % | J62: =J61/I61-1 -> 0.181796 | K62: =K61/J61-1 -> 0.11904954 | L62: =L61/K61-1 -> 0.075303909 | M62: =M61/L61-1 -> 0.041126334 | N62: =N61/M61-1 -> 0.011739515 | O62: =O61/N61-1 -> -0.015836824 | P62: =P61/O61-1 -> -0.043973345 | Q62: =Q61/P61-1 -> -0.075160063 | R62: =R61/Q61-1 -> -0.11280242
B64: Right of Use Asset
B65: Right of Use Asset | D65: =ConsolidatedBS!E10 -> 197.62 | E65: =ConsolidatedBS!F10 -> 183.66 | F65: =ConsolidatedBS!G10 -> 226.13 | G65: =ConsolidatedBS!H10 -> 271.99 | H65: =ConsolidatedBS!I10 -> 317.04 | I65: =H65*(1+I71) -> 317.04 | J65: =I68 -> 257.05339 | K65: =J68 -> 197.06678 | L65: =K68 -> 137.08017 | M65: =L68 -> 77.093563 | N65: =M68 -> 17.106954 | O65: =N68 -> -42.879655 | P65: =O68 -> -102.86626 | Q65: =P68 -> -162.85287 | R65: =Q68 -> -222.83948
B66: Addition during the year | I66: =H65*(I71) -> 0 | J66: =I65*(J71) -> 0 | K66: =J65*(K71) -> 0 | L66: =K65*(L71) -> 0 | M66: =L65*(M71) -> 0 | N66: =M65*(N71) -> 0 | O66: =N65*(O71) -> 0 | P66: =O65*(P71) -> 0 | ... R66: =Q65*(R71) -> 0
B67: Less : Depreciation | H67: =('ConsolidatedP&L'!I35*-1)/(SUM(ConsolidatedBS!I6,ConsolidatedBS!I10,ConsolidatedBS!I9,ConsolidatedBS!I11))*ConsolidatedBS!I10 -> 59.986609 | I67: =H67+I66/$C$114 -> 59.986609 | J67: =I67+J66/$C$114 -> 59.986609 | K67: =J67+K66/$C$114 -> 59.986609 | L67: =K67+L66/$C$114 -> 59.986609 | M67: =L67+M66/$C$114 -> 59.986609 | N67: =M67+N66/$C$114 -> 59.986609 | O67: =N67+O66/$C$114 -> 59.986609 | P67: =O67+P66/$C$114 -> 59.986609 | ... R67: =Q67+R66/$C$114 -> 59.986609
...

Sheet 3StatementModel
B2: ='Input Sheet'!C5 -> Eicher Motors
B3: 3 Statement Model
H4: Current Case: | I4: 0
T7: CAGR
F8: Actual | I8: Explicit Forecast Period | T8: 5 Years | U8: 3 Years
B9: In INR Crores unless stated otherwise | D9: =Controlsheet!D9 -> 2021 | E9: =Controlsheet!E9 -> 2022 | F9: =Controlsheet!F9 -> 2023 | G9: =Controlsheet!G9 -> 2024 | H9: =Controlsheet!H9 -> 2025 | I9: =H9+1 -> 2026 | J9: =I9+1 -> 2027 | K9: =J9+1 -> 2028 | L9: =K9+1 -> 2029 | M9: =L9+1 -> 2030 | N9: =M9+1 -> 2031 | O9: =N9+1 -> 2032 | P9: =O9+1 -> 2033 | ... R9: =Q9+1 -> 2035
A11: # | B11: Income Statement
B13: Revenue | D13: =Schedules!D13 -> 8720.35 | E13: =Schedules!E13 -> 10297.83 | F13: =Schedules!F13 -> 14442.18 | G13: =Schedules!G13 -> 16535.78 | H13: =Schedules!H13 -> 18870.35 | I13: =Schedules!I13 -> 21700.902 | J13: =Schedules!J13 -> 24793.281 | K13: =Schedules!K13 -> 28140.374 | ... R13: =Schedules!R13 -> 62625.983 | T13: =_xlfn.RRI($M$9-$H$9,H13,M13) -> 0.13495044 | U13: =_xlfn.RRI($M$9-$J$9,J13,M13) -> 0.12748337
B14: Less: Cost of Goods Sold | D14: =Schedules!D20 -> 5112.27 | E14: =Schedules!E20 -> 5955.68 | F14: =Schedules!F20 -> 8211.9 | G14: =Schedules!G20 -> 8980.65 | H14: =Schedules!H20 -> 10297.08 | I14: =Schedules!I20 -> 11935.496 | J14: =Schedules!J20 -> 13785.064 | K14: =Schedules!K20 -> 15814.89 | ... R14: =Schedules!R20 -> 35947.314 | T14: =_xlfn.RRI($M$9-$H$9,H14,M14) -> 0.14649575 | U14: =_xlfn.RRI($M$9-$J$9,J14,M14) -> 0.13952147
B15: Gross Profit | D15: =D13-D14 -> 3608.08 | E15: =E13-E14 -> 4342.15 | F15: =F13-F14 -> 6230.28 | G15: =G13-G14 -> 7555.13 | H15: =H13-H14 -> 8573.27 | I15: =I13-I14 -> 9765.4061 | J15: =J13-J14 -> 11008.217 | K15: =K13-K14 -> 12325.484 | ... S15: =S13-S14 -> 0 | T15: =_xlfn.RRI($M$9-$H$9,H15,M15) -> 0.12043201 | U15: =_xlfn.RRI($M$9-$J$9,J15,M15) -> 0.11203645
B17: Gross Margins | D17: =D15/D13 -> 0.41375404 | E17: =E15/E13 -> 0.4216568 | F17: =F15/F13 -> 0.43139471 | G17: =G15/G13 -> 0.45689589 | H17: =H15/H13 -> 0.45432491 | I17: =I15/I13 -> 0.45 | J17: =J15/J13 -> 0.444 | K17: =K15/K13 -> 0.438 | ... R17: =R15/R13 -> 0.426
B19: Less: SG&A Expenses (Excluding Depreciation & Interest)
B20: Employee Benefit Expense | D20: =Schedules!D28 -> 843.23 | E20: =Schedules!E28 -> 821.02 | F20: =Schedules!F28 -> 1001.93 | G20: =Schedules!G28 -> 1235.69 | H20: =Schedules!H28 -> 1391.23 | I20: =Schedules!I28 -> 1627.5677 | J20: =Schedules!J28 -> 1859.4961 | K20: =Schedules!K28 -> 2110.5281 | ... R20: =Schedules!R28 -> 4696.9487 | T20: =_xlfn.RRI($M$9-$H$9,H20,M20) -> 0.13884693 | U20: =_xlfn.RRI($M$9-$J$9,J20,M20) -> 0.12748337
B21: Consumption of Stores and machinery spares | D21: =Schedules!D33 -> 139.51 | E21: =Schedules!E33 -> 198.56 | F21: =Schedules!F33 -> 262.25 | G21: =Schedules!G33 -> 239.14 | H21: =Schedules!H33 -> 286.56 | I21: =Schedules!I33 -> 368.91534 | J21: =Schedules!J33 -> 421.48578 | K21: =Schedules!K33 -> 478.38636 | ... R21: =Schedules!R33 -> 1064.6417 | T21: =_xlfn.RRI($M$9-$H$9,H21,M21) -> 0.16085923 | U21: =_xlfn.RRI($M$9-$J$9,J21,M21) -> 0.12748337
B22: Freight and handling charges | D22: =Schedules!D38 -> 121.1 | E22: =Schedules!E38 -> 180.97 | F22: =Schedules!F38 -> 272.83 | G22: =Schedules!G38 -> 265.57 | H22: =Schedules!H38 -> 330.64 | I22: =Schedules!I38 -> 347.21444 | J22: =Schedules!J38 -> 396.6925 | K22: =Schedules!K38 -> 450.24598 | ... R22: =Schedules!R38 -> 1002.0157 | T22: =_xlfn.RRI($M$9-$H$9,H22,M22) -> 0.11451471 | U22: =_xlfn.RRI($M$9-$J$9,J22,M22) -> 0.12748337
B23: Selling and distribution expenses | D23: =Schedules!D43 -> 180.93 | E23: =Schedules!E43 -> 284.69 | F23: =Schedules!F43 -> 426.39 | G23: =Schedules!G43 -> 546.2 | H23: =Schedules!H43 -> 760.88 | I23: =Schedules!I43 -> 607.62527 | J23: =Schedules!J43 -> 694.21187 | K23: =Schedules!K43 -> 787.93047 | ... R23: =Schedules!R43 -> 1753.5275 | T23: =_xlfn.RRI($M$9-$H$9,H23,M23) -> 0.055118555 | U23: =_xlfn.RRI($M$9-$J$9,J23,M23) -> 0.12748337
B24: Other SG&A Expenses | D24: =Schedules!D48 -> 541.98 | E24: =Schedules!E48 -> 684.66 | F24: =Schedules!F48 -> 823.3 | G24: =Schedules!G48 -> 941.62 | H24: =Schedules!H48 -> 1091.93 | I24: =Schedules!I48 -> 1323.7551 | J24: =Schedules!J48 -> 1512.3901 | K24: =Schedules!K48 -> 1716.5628 | ... R24: =Schedules!R48 -> 3820.1849 | T24: =_xlfn.RRI($M$9-$H$9,H24,M24) -> 0.1469907 | U24: =_xlfn.RRI($M$9-$J$9,J24,M24) -> 0.12748337
B25: Earnings Before Interest,Taxes,Depreciation & Amortization | D25: =D15-SUM(D20:D24) -> 1781.33 | E25: =E15-SUM(E20:E24) -> 2172.25 | F25: =F15-SUM(F20:F24) -> 3443.58 | G25: =G15-SUM(G20:G24) -> 4326.91 | H25: =H15-SUM(H20:H24) -> 4712.03 | I25: =I15-SUM(I20:I24) -> 5490.3283 | J25: =J15-SUM(J20:J24) -> 6123.9404 | K25: =K15-SUM(K20:K24) -> 6781.8301 | ... R25: =R15-SUM(R20:R24) -> 14341.35 | T25: =_xlfn.RRI($M$9-$H$9,H25,M25) -> 0.11547123 | U25: =_xlfn.RRI($M$9-$J$9,J25,M25) -> 0.09940149
B27: EBITDA Margins | D27: =D25/D13 -> 0.20427276 | E27: =E25/E13 -> 0.2109425 | F27: =F25/F13 -> 0.23843907 | G27: =G25/G13 -> 0.26166954 | H27: =H25/H13 -> 0.24970549 | I27: =I25/I13 -> 0.253 | J27: =J25/J13 -> 0.247 | K27: =K25/K13 -> 0.241 | ... R27: =R25/R13 -> 0.229
B29: Less : Depreciation & Amortization | D29: ='ConsolidatedP&L'!E35*-1 -> 450.73 | E29: ='ConsolidatedP&L'!F35*-1 -> 451.93 | F29: ='ConsolidatedP&L'!G35*-1 -> 526.21 | G29: ='ConsolidatedP&L'!H35*-1 -> 597.6 | H29: ='ConsolidatedP&L'!I35*-1 -> 729.33 | I29: =Schedules!I116 -> 849.33 | J29: =Schedules!J116 -> 969.33 | K29: =Schedules!K116 -> 1089.33 | L29: =Schedules!L116 -> 1209.33 | M29: =Schedules!M116 -> 1329.33 | N29: =Schedules!N116 -> 1449.33 | O29: =Schedules!O116 -> 1569.33 | P29: =Schedules!P116 -> 1689.33 | ... R29: =Schedules!R116 -> 1929.33 | T29: =_xlfn.RRI($M$9-$H$9,H29,M29) -> 0.12756541 | U29: =_xlfn.RRI($M$9-$J$9,J29,M29) -> 0.11101618
B30: Earnings Before Interest & Taxes | D30: =D25-D29 -> 1330.6 | E30: =E25-E29 -> 1720.32 | F30: =F25-F29 -> 2917.37 | G30: =G25-G29 -> 3729.31 | H30: =H25-H29 -> 3982.7 | I30: =I25-I29 -> 4640.9983 | J30: =J25-J29 -> 5154.6104 | K30: =K25-K29 -> 5692.5001 | ... R30: =R25-R29 -> 12412.02 | T30: =_xlfn.RRI($M$9-$H$9,H30,M30) -> 0.1131987 | U30: =_xlfn.RRI($M$9-$J$9,J30,M30) -> 0.097189733
B32: EBIT Margins | D32: =D30/D13 -> 0.15258562 | E32: =E30/E13 -> 0.16705655 | F32: =F30/F13 -> 0.20200344 | G32: =G30/G13 -> 0.22552973 | H32: =H30/H13 -> 0.21105597 | I32: =I30/I13 -> 0.213862 | J32: =J30/J13 -> 0.20790352 | K32: =K30/K13 -> 0.20228943 | ... R32: =R30/R13 -> 0.19819282
B34: Less : Interest | D34: ='ConsolidatedP&L'!E38*-1 -> 16.45 | E34: ='ConsolidatedP&L'!F38*-1 -> 18.78 | F34: ='ConsolidatedP&L'!G38*-1 -> 28.02 | G34: ='ConsolidatedP&L'!H38*-1 -> 50.88 | H34: ='ConsolidatedP&L'!I38*-1 -> 54.34 | I34: =Schedules!I247 -> 22.238487 | J34: =Schedules!J247 -> 25.711568 | K34: =Schedules!K247 -> 25.110945 | L34: =Schedules!L247 -> 23.693931 | M34: =Schedules!M247 -> 21.332504 | N34: =Schedules!N247 -> 21.09397 | O34: =Schedules!O247 -> 23.625247 | P34: =Schedules!P247 -> 26.460276 | ... R34: =Schedules!R247 -> 33.191771
B35: Add : Other Income | D35: ='ConsolidatedP&L'!E39 -> 453.19 | E35: ='ConsolidatedP&L'!F39 -> 440.82 | F35: ='ConsolidatedP&L'!G39 -> 595.11 | G35: ='ConsolidatedP&L'!H39 -> 1075.87 | H35: ='ConsolidatedP&L'!I39 -> 1304.9 | I35: =Schedules!I254 -> 1128.4469 | J35: =Schedules!J254 -> 1289.2506 | K35: =Schedules!K254 -> 1463.2995 | L35: =Schedules!L254 -> 1649.8701 | M35: =Schedules!M254 -> 1847.8545 | N35: =Schedules!N254 -> 2069.5971 | O35: =Schedules!O254 -> 2317.9487 | P35: =Schedules!P254 -> 2596.1026 | ... R35: =Schedules!R254 -> 3256.5511
B36: Share of profit of joint venture (VE Commercial Vehicles Limited) | D36: ='ConsolidatedP&L'!E42 -> 31.13 | E36: ='ConsolidatedP&L'!F42 -> 60.15 | F36: ='ConsolidatedP&L'!G42 -> 315.17 | G36: ='ConsolidatedP&L'!H42 -> 447.72 | H36: ='ConsolidatedP&L'!I42 -> 699.81 | I36: =H36 -> 699.81 | J36: =I36 -> 699.81 | K36: =J36 -> 699.81 | L36: =K36 -> 699.81 | M36: =L36 -> 699.81 | N36: =M36 -> 699.81 | O36: =N36 -> 699.81 | P36: =O36 -> 699.81 | ... R36: =Q36 -> 699.81
B37: Profit Before Tax | D37: =D30-D34+SUM(D35:D36) -> 1798.47 | E37: =E30-E34+SUM(E35:E36) -> 2202.51 | F37: =F30-F34+SUM(F35:F36) -> 3799.63 | G37: =G30-G34+SUM(G35:G36) -> 5202.02 | H37: =H30-H34+SUM(H35:H36) -> 5933.07 | I37: =I30-I34+SUM(I35:I36) -> 6447.0168 | J37: =J30-J34+SUM(J35:J36) -> 7117.9595 | K37: =K30-K34+SUM(K35:K36) -> 7830.4987 | ... R37: =R30-R34+SUM(R35:R36) -> 16335.189
B39: Less: Taxes | D39: ='ConsolidatedP&L'!E45*-1 -> 451.5 | E39: ='ConsolidatedP&L'!F45*-1 -> 525.91 | F39: ='ConsolidatedP&L'!G45*-1 -> 885.69 | G39: ='ConsolidatedP&L'!H45*-1 -> 1201.01 | H39: ='ConsolidatedP&L'!I45*-1 -> 1198.63 | I39: =Schedules!I140*-1 -> 1160.2325 | J39: =Schedules!J140*-1 -> 1288.3794 | K39: =Schedules!K140*-1 -> 1423.6482 | L39: =Schedules!L140*-1 -> 1563.2477 | M39: =Schedules!M140*-1 -> 1704.8956 | N39: =Schedules!N140*-1 -> 1920.1133 | O39: =Schedules!O140*-1 -> 2164.0715 | P39: =Schedules!P140*-1 -> 2440.922 | ... R39: =Schedules!R140*-1 -> 3109.5617 | T39: =_xlfn.RRI($M$9-$H$9,H39,M39) -> 0.073006932 | U39: =_xlfn.RRI($M$9-$J$9,J39,M39) -> 0.097871059
B40: Net Income | D40: =D37-D39 -> 1346.97 | E40: =E37-E39 -> 1676.6 | F40: =F37-F39 -> 2913.94 | G40: =G37-G39 -> 4001.01 | H40: =H37-H39 -> 4734.44 | I40: =I37-I39 -> 5286.7843 | J40: =J37-J39 -> 5829.5801 | K40: =K37-K39 -> 6406.8505 | ... R40: =R37-R39 -> 13225.628 | T40: =_xlfn.RRI($M$9-$H$9,H40,M40) -> 0.10014165 | U40: =_xlfn.RRI($M$9-$J$9,J40,M40) -> 0.093850895
B42: Sales Growth % | E42: =IFERROR(E13/D13-1,"NM") -> 0.18089641 | F42: =IFERROR(F13/E13-1,"NM") -> 0.40244887 | G42: =IFERROR(G13/F13-1,"NM") -> 0.14496426 | H42: =IFERROR(H13/G13-1,"NM") -> 0.14118294 | I42: =IFERROR(I13/H13-1,"NM") -> 0.15 | J42: =IFERROR(J13/I13-1,"NM") -> 0.1425 | K42: =IFERROR(K13/J13-1,"NM") -> 0.135 | L42: =IFERROR(L13/K13-1,"NM") -> 0.1275 | ... R42: =IFERROR(R13/Q13-1,"NM") -> 0.12
B43: Gross Profit Margins % | D43: =IFERROR(D15/D13,"NM") -> 0.41375404 | E43: =IFERROR(E15/E13,"NM") -> 0.4216568 | F43: =IFERROR(F15/F13,"NM") -> 0.43139471 | G43: =IFERROR(G15/G13,"NM") -> 0.45689589 | H43: =IFERROR(H15/H13,"NM") -> 0.45432491 | I43: =IFERROR(I15/I13,"NM") -> 0.45 | J43: =IFERROR(J15/J13,"NM") -> 0.444 | K43: =IFERROR(K15/K13,"NM") -> 0.438 | ... R43: =IFERROR(R15/R13,"NM") -> 0.426
B44: EBITDA Margins % | D44: =IFERROR(D25/D13,"NM") -> 0.20427276 | E44: =IFERROR(E25/E13,"NM") -> 0.2109425 | F44: =IFERROR(F25/F13,"NM") -> 0.23843907 | G44: =IFERROR(G25/G13,"NM") -> 0.26166954 | H44: =IFERROR(H25/H13,"NM") -> 0.24970549 | I44: =IFERROR(I25/I13,"NM") -> 0.253 | J44: =IFERROR(J25/J13,"NM") -> 0.247 | K44: =IFERROR(K25/K13,"NM") -> 0.241 | ... R44: =IFERROR(R25/R13,"NM") -> 0.229
B45: EBIT Margins % | D45: =IFERROR(D30/D13,"NM") -> 0.15258562 | E45: =IFERROR(E30/E13,"NM") -> 0.16705655 | F45: =IFERROR(F30/F13,"NM") -> 0.20200344 | G45: =IFERROR(G30/G13,"NM") -> 0.22552973 | H45: =IFERROR(H30/H13,"NM") -> 0.21105597 | I45: =IFERROR(I30/I13,"NM") -> 0.213862 | J45: =IFERROR(J30/J13,"NM") -> 0.20790352 | K45: =IFERROR(K30/K13,"NM") -> 0.20228943 | ... R45: =IFERROR(R30/R13,"NM") -> 0.19819282
B46: Actual Tax Rate % | D46: =IFERROR(D39/D37,"NM") -> 0.25104672 | E46: =IFERROR(E39/E37,"NM") -> 0.23877758 | F46: =IFERROR(F39/F37,"NM") -> 0.23309901 | G46: =IFERROR(G39/G37,"NM") -> 0.23087378 | H46: =IFERROR(H39/H37,"NM") -> 0.20202526 | I46: =IFERROR(I39/I37,"NM") -> 0.17996424 | J46: =IFERROR(J39/J37,"NM") -> 0.18100404 | K46: =IFERROR(K39/K37,"NM") -> 0.18180811 | ... R46: =IFERROR(R39/R37,"NM") -> 0.19035969
B47: Net Income Margin % | D47: =IFERROR(D40/D13,"NM") -> 0.15446284 | E47: =IFERROR(E40/E13,"NM") -> 0.162811 | F47: =IFERROR(F40/F13,"NM") -> 0.20176594 | G47: =IFERROR(G40/G13,"NM") -> 0.24196077 | H47: =IFERROR(H40/H13,"NM") -> 0.25089307 | I47: =IFERROR(I40/I13,"NM") -> 0.24362048 | J47: =IFERROR(J40/J13,"NM") -> 0.23512741 | K47: =IFERROR(K40/K13,"NM") -> 0.22767467 | ... R47: =IFERROR(R40/R13,"NM") -> 0.21118435
A49: # | B49: Balance Sheet
B51: Assets
B52: Non Current Assets
B53: Property Plant & Equipment | D53: =ConsolidatedBS!E6 -> 1894.51 | E53: =ConsolidatedBS!F6 -> 1910.78 | F53: =ConsolidatedBS!G6 -> 1999.65 | G53: =ConsolidatedBS!H6 -> 1950.26 | H53: =ConsolidatedBS!I6 -> 2268.7 | I53: =Schedules!I61 -> 2919.4431 | J53: =Schedules!J61 -> 3450.1861 | K53: =Schedules!K61 -> 3860.9292 | L53: =Schedules!L61 -> 4151.6722 | M53: =Schedules!M61 -> 4322.4153 | N53: =Schedules!N61 -> 4373.1584 | O53: =Schedules!O61 -> 4303.9014 | P53: =Schedules!P61 -> 4114.6445 | ... R53: =Schedules!R61 -> 3376.1306
B54: Right of Use Asset | D54: =ConsolidatedBS!E10 -> 197.62 | E54: =ConsolidatedBS!F10 -> 183.66 | F54: =ConsolidatedBS!G10 -> 226.13 | G54: =ConsolidatedBS!H10 -> 271.99 | H54: =ConsolidatedBS!I10 -> 317.04 | I54: =Schedules!I68 -> 257.05339 | J54: =Schedules!J68 -> 197.06678 | K54: =Schedules!K68 -> 137.08017 | L54: =Schedules!L68 -> 77.093563 | M54: =Schedules!M68 -> 17.106954 | N54: =Schedules!N68 -> -42.879655 | O54: =Schedules!O68 -> -102.86626 | P54: =Schedules!P68 -> -162.85287 | ... R54: =Schedules!R68 -> -282.82609
B55: Capital Work in Progress | D55: =ConsolidatedBS!E7 -> 63.91 | E55: =ConsolidatedBS!F7 -> 133.98 | F55: =ConsolidatedBS!G7 -> 77.75 | G55: =ConsolidatedBS!H7 -> 211.65 | H55: =ConsolidatedBS!I7 -> 110.3 | I55: =Schedules!I74 -> 0 | J55: =Schedules!J74 -> 0 | K55: =Schedules!K74 -> 0 | L55: =Schedules!L74 -> 0 | M55: =Schedules!M74 -> 0 | N55: =Schedules!N74 -> 0 | O55: =Schedules!O74 -> 0 | P55: =Schedules!P74 -> 0 | ... R55: =Schedules!R74 -> 0
...

Sheet CommonSizeStatement
B2: ='Input Sheet'!C5 -> Eicher Motors
B3: Common Size Statement Model
H4: Current Case: | I4: 0
F8: Actual | I8: Explicit Forecast Period
B9: In INR Crores unless stated otherwise | D9: =Controlsheet!D9 -> 2021 | E9: =Controlsheet!E9 -> 2022 | F9: =Controlsheet!F9 -> 2023 | G9: =Controlsheet!G9 -> 2024 | H9: =Controlsheet!H9 -> 2025 | I9: =H9+1 -> 2026 | J9: =I9+1 -> 2027 | K9: =J9+1 -> 2028 | L9: =K9+1 -> 2029 | M9: =L9+1 -> 2030
A11: # | B11: Income Statement
B13: Revenue | D13: ='3StatementModel'!D13/'3StatementModel'!D$13 -> 1 | E13: ='3StatementModel'!E13/'3StatementModel'!E$13 -> 1 | F13: ='3StatementModel'!F13/'3StatementModel'!F$13 -> 1 | G13: ='3StatementModel'!G13/'3StatementModel'!G$13 -> 1 | H13: ='3StatementModel'!H13/'3StatementModel'!H$13 -> 1 | I13: ='3StatementModel'!I13/'3StatementModel'!I$13 -> 1 | J13: ='3StatementModel'!J13/'3StatementModel'!J$13 -> 1 | K13: ='3StatementModel'!K13/'3StatementModel'!K$13 -> 1 | ... M13: ='3StatementModel'!M13/'3StatementModel'!M$13 -> 1
B14: Less: Cost of Goods Sold | D14: ='3StatementModel'!D14/'3StatementModel'!D$13 -> 0.58624596 | E14: ='3StatementModel'!E14/'3StatementModel'!E$13 -> 0.5783432 | F14: ='3StatementModel'!F14/'3StatementModel'!F$13 -> 0.56860529 | G14: ='3StatementModel'!G14/'3StatementModel'!G$13 -> 0.54310411 | H14: ='3StatementModel'!H14/'3StatementModel'!H$13 -> 0.54567509 | I14: ='3StatementModel'!I14/'3StatementModel'!I$13 -> 0.55 | J14: ='3StatementModel'!J14/'3StatementModel'!J$13 -> 0.556 | K14: ='3StatementModel'!K14/'3StatementModel'!K$13 -> 0.562 | ... M14: ='3StatementModel'!M14/'3StatementModel'!M$13 -> 0.574
B15: Gross Profit | D15: ='3StatementModel'!D15/'3StatementModel'!D$13 -> 0.41375404 | E15: ='3StatementModel'!E15/'3StatementModel'!E$13 -> 0.4216568 | F15: ='3StatementModel'!F15/'3StatementModel'!F$13 -> 0.43139471 | G15: ='3StatementModel'!G15/'3StatementModel'!G$13 -> 0.45689589 | H15: ='3StatementModel'!H15/'3StatementModel'!H$13 -> 0.45432491 | I15: ='3StatementModel'!I15/'3StatementModel'!I$13 -> 0.45 | J15: ='3StatementModel'!J15/'3StatementModel'!J$13 -> 0.444 | K15: ='3StatementModel'!K15/'3StatementModel'!K$13 -> 0.438 | ... M15: ='3StatementModel'!M15/'3StatementModel'!M$13 -> 0.426
B17: Less: SG&A Expenses (Excluding Depreciation & Interest)
B18: Employee Benefit Expense | D18: ='3StatementModel'!D20/'3StatementModel'!D$13 -> 0.096696807 | E18: ='3StatementModel'!E20/'3StatementModel'!E$13 -> 0.079727477 | F18: ='3StatementModel'!F20/'3StatementModel'!F$13 -> 0.069375261 | G18: ='3StatementModel'!G20/'3StatementModel'!G$13 -> 0.074728256 | H18: ='3StatementModel'!H20/'3StatementModel'!H$13 -> 0.073725713 | I18: ='3StatementModel'!I20/'3StatementModel'!I$13 -> 0.075 | J18: ='3StatementModel'!J20/'3StatementModel'!J$13 -> 0.075 | K18: ='3StatementModel'!K20/'3StatementModel'!K$13 -> 0.075 | ... M18: ='3StatementModel'!M20/'3StatementModel'!M$13 -> 0.075
B19: Consumption of Stores and machinery spares | D19: ='3StatementModel'!D21/'3StatementModel'!D$13 -> 0.015998211 | E19: ='3StatementModel'!E21/'3StatementModel'!E$13 -> 0.019281732 | F19: ='3StatementModel'!F21/'3StatementModel'!F$13 -> 0.018158616 | G19: ='3StatementModel'!G21/'3StatementModel'!G$13 -> 0.014461973 | H19: ='3StatementModel'!H21/'3StatementModel'!H$13 -> 0.015185728 | I19: ='3StatementModel'!I21/'3StatementModel'!I$13 -> 0.017 | J19: ='3StatementModel'!J21/'3StatementModel'!J$13 -> 0.017 | K19: ='3StatementModel'!K21/'3StatementModel'!K$13 -> 0.017 | ... M19: ='3StatementModel'!M21/'3StatementModel'!M$13 -> 0.017
B20: Freight and handling charges | D20: ='3StatementModel'!D22/'3StatementModel'!D$13 -> 0.013887057 | E20: ='3StatementModel'!E22/'3StatementModel'!E$13 -> 0.017573605 | F20: ='3StatementModel'!F22/'3StatementModel'!F$13 -> 0.018891192 | G20: ='3StatementModel'!G22/'3StatementModel'!G$13 -> 0.016060325 | H20: ='3StatementModel'!H22/'3StatementModel'!H$13 -> 0.017521668 | I20: ='3StatementModel'!I22/'3StatementModel'!I$13 -> 0.016 | J20: ='3StatementModel'!J22/'3StatementModel'!J$13 -> 0.016 | K20: ='3StatementModel'!K22/'3StatementModel'!K$13 -> 0.016 | ... M20: ='3StatementModel'!M22/'3StatementModel'!M$13 -> 0.016
B21: Selling and distribution expenses | D21: ='3StatementModel'!D23/'3StatementModel'!D$13 -> 0.02074802 | E21: ='3StatementModel'!E23/'3StatementModel'!E$13 -> 0.02764563 | F21: ='3StatementModel'!F23/'3StatementModel'!F$13 -> 0.029523936 | G21: ='3StatementModel'!G23/'3StatementModel'!G$13 -> 0.033031402 | H21: ='3StatementModel'!H23/'3StatementModel'!H$13 -> 0.040321457 | I21: ='3StatementModel'!I23/'3StatementModel'!I$13 -> 0.028 | J21: ='3StatementModel'!J23/'3StatementModel'!J$13 -> 0.028 | K21: ='3StatementModel'!K23/'3StatementModel'!K$13 -> 0.028 | ... M21: ='3StatementModel'!M23/'3StatementModel'!M$13 -> 0.028
B22: Other SG&A Expenses | D22: ='3StatementModel'!D24/'3StatementModel'!D$13 -> 0.062151175 | E22: ='3StatementModel'!E24/'3StatementModel'!E$13 -> 0.066485852 | F22: ='3StatementModel'!F24/'3StatementModel'!F$13 -> 0.057006629 | G22: ='3StatementModel'!G24/'3StatementModel'!G$13 -> 0.056944396 | H22: ='3StatementModel'!H24/'3StatementModel'!H$13 -> 0.057864851 | I22: ='3StatementModel'!I24/'3StatementModel'!I$13 -> 0.061 | J22: ='3StatementModel'!J24/'3StatementModel'!J$13 -> 0.061 | K22: ='3StatementModel'!K24/'3StatementModel'!K$13 -> 0.061 | ... M22: ='3StatementModel'!M24/'3StatementModel'!M$13 -> 0.061
B23: Earnings Before Interest,Taxes,Depreciation & Amortization | D23: ='3StatementModel'!D25/'3StatementModel'!D$13 -> 0.20427276 | E23: ='3StatementModel'!E25/'3StatementModel'!E$13 -> 0.2109425 | F23: ='3StatementModel'!F25/'3StatementModel'!F$13 -> 0.23843907 | G23: ='3StatementModel'!G25/'3StatementModel'!G$13 -> 0.26166954 | H23: ='3StatementModel'!H25/'3StatementModel'!H$13 -> 0.24970549 | I23: ='3StatementModel'!I25/'3StatementModel'!I$13 -> 0.253 | J23: ='3StatementModel'!J25/'3StatementModel'!J$13 -> 0.247 | K23: ='3StatementModel'!K25/'3StatementModel'!K$13 -> 0.241 | ... M23: ='3StatementModel'!M25/'3StatementModel'!M$13 -> 0.229
B25: Less : Depreciation & Amortization | D25: ='3StatementModel'!D29/'3StatementModel'!D$13 -> 0.051687146 | E25: ='3StatementModel'!E29/'3StatementModel'!E$13 -> 0.043885945 | F25: ='3StatementModel'!F29/'3StatementModel'!F$13 -> 0.036435635 | G25: ='3StatementModel'!G29/'3StatementModel'!G$13 -> 0.036139813 | H25: ='3StatementModel'!H29/'3StatementModel'!H$13 -> 0.038649522 | I25: ='3StatementModel'!I29/'3StatementModel'!I$13 -> 0.039138004 | J25: ='3StatementModel'!J29/'3StatementModel'!J$13 -> 0.039096479 | K25: ='3StatementModel'!K29/'3StatementModel'!K$13 -> 0.038710573 | ... M25: ='3StatementModel'!M29/'3StatementModel'!M$13 -> 0.037408334
B26: Earnings Before Interest & Taxes | D26: ='3StatementModel'!D30/'3StatementModel'!D$15 -> 0.3687834 | E26: ='3StatementModel'!E30/'3StatementModel'!E$15 -> 0.39619083 | F26: ='3StatementModel'!F30/'3StatementModel'!F$15 -> 0.46825664 | G26: ='3StatementModel'!G30/'3StatementModel'!G$15 -> 0.49361295 | H26: ='3StatementModel'!H30/'3StatementModel'!H$15 -> 0.46454853 | I26: ='3StatementModel'!I30/'3StatementModel'!I$15 -> 0.47524888 | J26: ='3StatementModel'!J30/'3StatementModel'!J$15 -> 0.46825117 | K26: ='3StatementModel'!K30/'3StatementModel'!K$15 -> 0.46184801 | ... M26: ='3StatementModel'!M30/'3StatementModel'!M$15 -> 0.44974569
B28: Less : Interest | D28: ='3StatementModel'!D34/'3StatementModel'!D$13 -> 0.0018863922 | E28: ='3StatementModel'!E34/'3StatementModel'!E$13 -> 0.0018236852 | F28: ='3StatementModel'!F34/'3StatementModel'!F$13 -> 0.0019401503 | G28: ='3StatementModel'!G34/'3StatementModel'!G$13 -> 0.003076964 | H28: ='3StatementModel'!H34/'3StatementModel'!H$13 -> 0.0028796498 | I28: ='3StatementModel'!I34/'3StatementModel'!I$13 -> 0.0010247724 | J28: ='3StatementModel'!J34/'3StatementModel'!J$13 -> 0.0010370377 | K28: ='3StatementModel'!K34/'3StatementModel'!K$13 -> 0.00089234581 | ... M28: ='3StatementModel'!M34/'3StatementModel'!M$13 -> 0.0006003125
B29: Add : Other Income | D29: ='3StatementModel'!D35/'3StatementModel'!D$13 -> 0.051969244 | E29: ='3StatementModel'!E35/'3StatementModel'!E$13 -> 0.042807077 | F29: ='3StatementModel'!F35/'3StatementModel'!F$13 -> 0.041206383 | G29: ='3StatementModel'!G35/'3StatementModel'!G$13 -> 0.065063154 | H29: ='3StatementModel'!H35/'3StatementModel'!H$13 -> 0.069150811 | I29: ='3StatementModel'!I35/'3StatementModel'!I$13 -> 0.052 | J29: ='3StatementModel'!J35/'3StatementModel'!J$13 -> 0.052 | K29: ='3StatementModel'!K35/'3StatementModel'!K$13 -> 0.052 | ... M29: ='3StatementModel'!M35/'3StatementModel'!M$13 -> 0.052
B30: Share of profit of joint venture (VE Commercial Vehicles Limited) | D30: ='3StatementModel'!D36/'3StatementModel'!D$13 -> 0.0035698108 | E30: ='3StatementModel'!E36/'3StatementModel'!E$13 -> 0.0058410364 | F30: ='3StatementModel'!F36/'3StatementModel'!F$13 -> 0.021822883 | G30: ='3StatementModel'!G36/'3StatementModel'!G$13 -> 0.027075832 | H30: ='3StatementModel'!H36/'3StatementModel'!H$13 -> 0.037085163 | I30: ='3StatementModel'!I36/'3StatementModel'!I$13 -> 0.032247968 | J30: ='3StatementModel'!J36/'3StatementModel'!J$13 -> 0.028225792 | K30: ='3StatementModel'!K36/'3StatementModel'!K$13 -> 0.024868539 | ... M30: ='3StatementModel'!M36/'3StatementModel'!M$13 -> 0.019693173
B31: Profit Before Tax | D31: ='3StatementModel'!D37/'3StatementModel'!D$13 -> 0.20623828 | E31: ='3StatementModel'!E37/'3StatementModel'!E$13 -> 0.21388098 | F31: ='3StatementModel'!F37/'3StatementModel'!F$13 -> 0.26309255 | G31: ='3StatementModel'!G37/'3StatementModel'!G$13 -> 0.31459175 | H31: ='3StatementModel'!H37/'3StatementModel'!H$13 -> 0.31441229 | I31: ='3StatementModel'!I37/'3StatementModel'!I$13 -> 0.29708519 | J31: ='3StatementModel'!J37/'3StatementModel'!J$13 -> 0.28709228 | K31: ='3StatementModel'!K37/'3StatementModel'!K$13 -> 0.27826562 | ... M31: ='3StatementModel'!M37/'3StatementModel'!M$13 -> 0.26268453
B33: Less: Taxes | D33: ='3StatementModel'!D39/'3StatementModel'!D$13 -> 0.051775445 | E33: ='3StatementModel'!E39/'3StatementModel'!E$13 -> 0.051069983 | F33: ='3StatementModel'!F39/'3StatementModel'!F$13 -> 0.061326614 | G33: ='3StatementModel'!G39/'3StatementModel'!G$13 -> 0.072630986 | H33: ='3StatementModel'!H39/'3StatementModel'!H$13 -> 0.063519225 | I33: ='3StatementModel'!I39/'3StatementModel'!I$13 -> 0.053464711 | J33: ='3StatementModel'!J39/'3StatementModel'!J$13 -> 0.051964861 | K33: ='3StatementModel'!K39/'3StatementModel'!K$13 -> 0.050590947 | ... M33: ='3StatementModel'!M39/'3StatementModel'!M$13 -> 0.047977028
B34: Net Income | D34: ='3StatementModel'!D40/'3StatementModel'!D$13 -> 0.15446284 | E34: ='3StatementModel'!E40/'3StatementModel'!E$13 -> 0.162811 | F34: ='3StatementModel'!F40/'3StatementModel'!F$13 -> 0.20176594 | G34: ='3StatementModel'!G40/'3StatementModel'!G$13 -> 0.24196077 | H34: ='3StatementModel'!H40/'3StatementModel'!H$13 -> 0.25089307 | I34: ='3StatementModel'!I40/'3StatementModel'!I$13 -> 0.24362048 | J34: ='3StatementModel'!J40/'3StatementModel'!J$13 -> 0.23512741 | K34: ='3StatementModel'!K40/'3StatementModel'!K$13 -> 0.22767467 | ... M34: ='3StatementModel'!M40/'3StatementModel'!M$13 -> 0.2147075
A36: # | B36: Balance Sheet
B38: Assets
B39: Non Current Assets
B40: Property Plant & Equipment | D40: ='3StatementModel'!D53/'3StatementModel'!D$76 -> 0.13013988 | E40: ='3StatementModel'!E53/'3StatementModel'!E$76 -> 0.11843262 | F40: ='3StatementModel'!F53/'3StatementModel'!F$76 -> 0.10434283 | G40: ='3StatementModel'!G53/'3StatementModel'!G$76 -> 0.084343883 | H40: ='3StatementModel'!H53/'3StatementModel'!H$76 -> 0.083474223 | I40: ='3StatementModel'!I53/'3StatementModel'!I$76 -> 0.097077907 | J40: ='3StatementModel'!J53/'3StatementModel'!J$76 -> 0.10500333 | K40: ='3StatementModel'!K53/'3StatementModel'!K$76 -> 0.10849321 | ... M40: ='3StatementModel'!M53/'3StatementModel'!M$76 -> 0.10825618
B41: Right of Use Asset | D41: ='3StatementModel'!D54/'3StatementModel'!D$76 -> 0.013575142 | E41: ='3StatementModel'!E54/'3StatementModel'!E$76 -> 0.011383484 | F41: ='3StatementModel'!F54/'3StatementModel'!F$76 -> 0.011799587 | G41: ='3StatementModel'!G54/'3StatementModel'!G$76 -> 0.011762889 | H41: ='3StatementModel'!H54/'3StatementModel'!H$76 -> 0.011665124 | I41: ='3StatementModel'!I54/'3StatementModel'!I$76 -> 0.008547591 | J41: ='3StatementModel'!J54/'3StatementModel'!J$76 -> 0.0059975514 | K41: ='3StatementModel'!K54/'3StatementModel'!K$76 -> 0.0038519917 | ... M41: ='3StatementModel'!M54/'3StatementModel'!M$76 -> 0.00042844876
B42: Capital Work in Progress | D42: ='3StatementModel'!D55/'3StatementModel'!D$76 -> 0.0043901799 | E42: ='3StatementModel'!E55/'3StatementModel'!E$76 -> 0.0083042538 | F42: ='3StatementModel'!F55/'3StatementModel'!F$76 -> 0.0040570375 | G42: ='3StatementModel'!G55/'3StatementModel'!G$76 -> 0.0091533349 | H42: ='3StatementModel'!H55/'3StatementModel'!H$76 -> 0.0040583624 | I42: ='3StatementModel'!I55/'3StatementModel'!I$76 -> 0 | J42: ='3StatementModel'!J55/'3StatementModel'!J$76 -> 0 | K42: ='3StatementModel'!K55/'3StatementModel'!K$76 -> 0 | ... M42: ='3StatementModel'!M55/'3StatementModel'!M$76 -> 0
